try {
    throw "error"
} catch {
    func(e) { "success" }
}
